[2025-03-21T13:51:28.727+0000] {local_task_job_runner.py:123} INFO - ::group::Pre task execution logs
[2025-03-21T13:51:28.755+0000] {taskinstance.py:2614} INFO - Dependencies all met for dep_context=non-requeueable deps ti=<TaskInstance: data_ingestion_gcs_dag.download_and_unzip_dataset_task manual__2025-03-21T13:51:26.141451+00:00 [queued]>
[2025-03-21T13:51:28.769+0000] {taskinstance.py:2614} INFO - Dependencies all met for dep_context=requeueable deps ti=<TaskInstance: data_ingestion_gcs_dag.download_and_unzip_dataset_task manual__2025-03-21T13:51:26.141451+00:00 [queued]>
[2025-03-21T13:51:28.770+0000] {taskinstance.py:2867} INFO - Starting attempt 1 of 2
[2025-03-21T13:51:28.789+0000] {taskinstance.py:2890} INFO - Executing <Task(BashOperator): download_and_unzip_dataset_task> on 2025-03-21 13:51:26.141451+00:00
[2025-03-21T13:51:28.802+0000] {warnings.py:112} WARNING - /home/***/.local/lib/python3.12/site-packages/***/task/task_runner/standard_task_runner.py:70: DeprecationWarning: This process (pid=163) is multi-threaded, use of fork() may lead to deadlocks in the child.
  pid = os.fork()

[2025-03-21T13:51:28.805+0000] {standard_task_runner.py:72} INFO - Started process 165 to run task
[2025-03-21T13:51:28.806+0000] {standard_task_runner.py:104} INFO - Running: ['***', 'tasks', 'run', 'data_ingestion_gcs_dag', 'download_and_unzip_dataset_task', 'manual__2025-03-21T13:51:26.141451+00:00', '--job-id', '32', '--raw', '--subdir', 'DAGS_FOLDER/data_ingestion_gcs_dag.py', '--cfg-path', '/tmp/tmpggkzsb47']
[2025-03-21T13:51:28.811+0000] {standard_task_runner.py:105} INFO - Job 32: Subtask download_and_unzip_dataset_task
[2025-03-21T13:51:28.883+0000] {task_command.py:467} INFO - Running <TaskInstance: data_ingestion_gcs_dag.download_and_unzip_dataset_task manual__2025-03-21T13:51:26.141451+00:00 [running]> on host 4791d3610749
[2025-03-21T13:51:29.028+0000] {taskinstance.py:3134} INFO - Exporting env vars: AIRFLOW_CTX_DAG_OWNER='***' AIRFLOW_CTX_DAG_ID='data_ingestion_gcs_dag' AIRFLOW_CTX_TASK_ID='download_and_unzip_dataset_task' AIRFLOW_CTX_EXECUTION_DATE='2025-03-21T13:51:26.141451+00:00' AIRFLOW_CTX_TRY_NUMBER='1' AIRFLOW_CTX_DAG_RUN_ID='manual__2025-03-21T13:51:26.141451+00:00'
[2025-03-21T13:51:29.030+0000] {taskinstance.py:732} INFO - ::endgroup::
[2025-03-21T13:51:29.052+0000] {subprocess.py:78} INFO - Tmp dir root location: /tmp
[2025-03-21T13:51:29.053+0000] {subprocess.py:88} INFO - Running command: ['/usr/bin/bash', '-c', 'curl -sSL https://github.com/DataTalksClub/nyc-tlc-data/releases/download/yellow/yellow_tripdata_2021-01.csv.gz > /opt/***/yellow_tripdata_2021-01.csv.gz && gunzip /opt/***/yellow_tripdata_2021-01.csv.gz']
[2025-03-21T13:51:29.076+0000] {subprocess.py:99} INFO - Output:
[2025-03-21T13:51:30.898+0000] {subprocess.py:106} INFO - gzip: /opt/***/yellow_tripdata_2021-01.csv already exists;	not overwritten
[2025-03-21T13:51:30.899+0000] {subprocess.py:110} INFO - Command exited with return code 2
[2025-03-21T13:51:30.918+0000] {taskinstance.py:3313} ERROR - Task failed with exception
Traceback (most recent call last):
  File "/home/airflow/.local/lib/python3.12/site-packages/airflow/models/taskinstance.py", line 768, in _execute_task
    result = _execute_callable(context=context, **execute_callable_kwargs)
             ^^^^^^^^^^^^^^^^^^^^^^^^^^^^^^^^^^^^^^^^^^^^^^^^^^^^^^^^^^^^^
  File "/home/airflow/.local/lib/python3.12/site-packages/airflow/models/taskinstance.py", line 734, in _execute_callable
    return ExecutionCallableRunner(
           ^^^^^^^^^^^^^^^^^^^^^^^^
  File "/home/airflow/.local/lib/python3.12/site-packages/airflow/utils/operator_helpers.py", line 252, in run
    return self.func(*args, **kwargs)
           ^^^^^^^^^^^^^^^^^^^^^^^^^^
  File "/home/airflow/.local/lib/python3.12/site-packages/airflow/models/baseoperator.py", line 424, in wrapper
    return func(self, *args, **kwargs)
           ^^^^^^^^^^^^^^^^^^^^^^^^^^^
  File "/home/airflow/.local/lib/python3.12/site-packages/airflow/operators/bash.py", line 276, in execute
    raise AirflowException(
airflow.exceptions.AirflowException: Bash command failed. The command returned a non-zero exit code 2.
[2025-03-21T13:51:30.932+0000] {taskinstance.py:1226} INFO - Marking task as UP_FOR_RETRY. dag_id=data_ingestion_gcs_dag, task_id=download_and_unzip_dataset_task, run_id=manual__2025-03-21T13:51:26.141451+00:00, execution_date=20250321T135126, start_date=20250321T135128, end_date=20250321T135130
[2025-03-21T13:51:30.982+0000] {taskinstance.py:341} INFO - ::group::Post task execution logs
[2025-03-21T13:51:30.983+0000] {standard_task_runner.py:124} ERROR - Failed to execute job 32 for task download_and_unzip_dataset_task (Bash command failed. The command returned a non-zero exit code 2.; 165)
Traceback (most recent call last):
  File "/home/airflow/.local/lib/python3.12/site-packages/airflow/task/task_runner/standard_task_runner.py", line 117, in _start_by_fork
    ret = args.func(args, dag=self.dag)
          ^^^^^^^^^^^^^^^^^^^^^^^^^^^^^
  File "/home/airflow/.local/lib/python3.12/site-packages/airflow/cli/cli_config.py", line 49, in command
    return func(*args, **kwargs)
           ^^^^^^^^^^^^^^^^^^^^^
  File "/home/airflow/.local/lib/python3.12/site-packages/airflow/utils/cli.py", line 116, in wrapper
    return f(*args, **kwargs)
           ^^^^^^^^^^^^^^^^^^
  File "/home/airflow/.local/lib/python3.12/site-packages/airflow/cli/commands/task_command.py", line 483, in task_run
    task_return_code = _run_task_by_selected_method(args, _dag, ti)
                       ^^^^^^^^^^^^^^^^^^^^^^^^^^^^^^^^^^^^^^^^^^^^
  File "/home/airflow/.local/lib/python3.12/site-packages/airflow/cli/commands/task_command.py", line 256, in _run_task_by_selected_method
    return _run_raw_task(args, ti)
           ^^^^^^^^^^^^^^^^^^^^^^^
  File "/home/airflow/.local/lib/python3.12/site-packages/airflow/cli/commands/task_command.py", line 341, in _run_raw_task
    return ti._run_raw_task(
           ^^^^^^^^^^^^^^^^^
  File "/home/airflow/.local/lib/python3.12/site-packages/airflow/utils/session.py", line 97, in wrapper
    return func(*args, session=session, **kwargs)
           ^^^^^^^^^^^^^^^^^^^^^^^^^^^^^^^^^^^^^^
  File "/home/airflow/.local/lib/python3.12/site-packages/airflow/models/taskinstance.py", line 3006, in _run_raw_task
    return _run_raw_task(
           ^^^^^^^^^^^^^^
  File "/home/airflow/.local/lib/python3.12/site-packages/airflow/models/taskinstance.py", line 274, in _run_raw_task
    TaskInstance._execute_task_with_callbacks(
  File "/home/airflow/.local/lib/python3.12/site-packages/airflow/models/taskinstance.py", line 3161, in _execute_task_with_callbacks
    result = self._execute_task(context, task_orig)
             ^^^^^^^^^^^^^^^^^^^^^^^^^^^^^^^^^^^^^^
  File "/home/airflow/.local/lib/python3.12/site-packages/airflow/models/taskinstance.py", line 3185, in _execute_task
    return _execute_task(self, context, task_orig)
           ^^^^^^^^^^^^^^^^^^^^^^^^^^^^^^^^^^^^^^^
  File "/home/airflow/.local/lib/python3.12/site-packages/airflow/models/taskinstance.py", line 768, in _execute_task
    result = _execute_callable(context=context, **execute_callable_kwargs)
             ^^^^^^^^^^^^^^^^^^^^^^^^^^^^^^^^^^^^^^^^^^^^^^^^^^^^^^^^^^^^^
  File "/home/airflow/.local/lib/python3.12/site-packages/airflow/models/taskinstance.py", line 734, in _execute_callable
    return ExecutionCallableRunner(
           ^^^^^^^^^^^^^^^^^^^^^^^^
  File "/home/airflow/.local/lib/python3.12/site-packages/airflow/utils/operator_helpers.py", line 252, in run
    return self.func(*args, **kwargs)
           ^^^^^^^^^^^^^^^^^^^^^^^^^^
  File "/home/airflow/.local/lib/python3.12/site-packages/airflow/models/baseoperator.py", line 424, in wrapper
    return func(self, *args, **kwargs)
           ^^^^^^^^^^^^^^^^^^^^^^^^^^^
  File "/home/airflow/.local/lib/python3.12/site-packages/airflow/operators/bash.py", line 276, in execute
    raise AirflowException(
airflow.exceptions.AirflowException: Bash command failed. The command returned a non-zero exit code 2.
[2025-03-21T13:51:31.031+0000] {local_task_job_runner.py:266} INFO - Task exited with return code 1
[2025-03-21T13:51:31.066+0000] {taskinstance.py:3901} INFO - 0 downstream tasks scheduled from follow-on schedule check
[2025-03-21T13:51:31.069+0000] {local_task_job_runner.py:245} INFO - ::endgroup::
