[2025-03-21T11:31:32.526+0000] {local_task_job_runner.py:123} INFO - ::group::Pre task execution logs
[2025-03-21T11:31:32.559+0000] {taskinstance.py:2614} INFO - Dependencies all met for dep_context=non-requeueable deps ti=<TaskInstance: data_ingestion_gcs_dag.format_to_parquet_task manual__2025-03-21T11:26:23.009689+00:00 [queued]>
[2025-03-21T11:31:32.573+0000] {taskinstance.py:2614} INFO - Dependencies all met for dep_context=requeueable deps ti=<TaskInstance: data_ingestion_gcs_dag.format_to_parquet_task manual__2025-03-21T11:26:23.009689+00:00 [queued]>
[2025-03-21T11:31:32.574+0000] {taskinstance.py:2867} INFO - Starting attempt 2 of 2
[2025-03-21T11:31:32.595+0000] {taskinstance.py:2890} INFO - Executing <Task(PythonOperator): format_to_parquet_task> on 2025-03-21 11:26:23.009689+00:00
[2025-03-21T11:31:32.609+0000] {warnings.py:112} WARNING - /home/***/.local/lib/python3.12/site-packages/***/task/task_runner/standard_task_runner.py:70: DeprecationWarning: This process (pid=1327) is multi-threaded, use of fork() may lead to deadlocks in the child.
  pid = os.fork()

[2025-03-21T11:31:32.612+0000] {standard_task_runner.py:72} INFO - Started process 1329 to run task
[2025-03-21T11:31:32.613+0000] {standard_task_runner.py:104} INFO - Running: ['***', 'tasks', 'run', 'data_ingestion_gcs_dag', 'format_to_parquet_task', 'manual__2025-03-21T11:26:23.009689+00:00', '--job-id', '21', '--raw', '--subdir', 'DAGS_FOLDER/data_ingestion_gcs_dag.py', '--cfg-path', '/tmp/tmpkln6ngk2']
[2025-03-21T11:31:32.617+0000] {standard_task_runner.py:105} INFO - Job 21: Subtask format_to_parquet_task
[2025-03-21T11:31:32.688+0000] {task_command.py:467} INFO - Running <TaskInstance: data_ingestion_gcs_dag.format_to_parquet_task manual__2025-03-21T11:26:23.009689+00:00 [running]> on host 4791d3610749
[2025-03-21T11:31:32.816+0000] {taskinstance.py:3134} INFO - Exporting env vars: AIRFLOW_CTX_DAG_OWNER='***' AIRFLOW_CTX_DAG_ID='data_ingestion_gcs_dag' AIRFLOW_CTX_TASK_ID='format_to_parquet_task' AIRFLOW_CTX_EXECUTION_DATE='2025-03-21T11:26:23.009689+00:00' AIRFLOW_CTX_TRY_NUMBER='2' AIRFLOW_CTX_DAG_RUN_ID='manual__2025-03-21T11:26:23.009689+00:00'
[2025-03-21T11:31:32.818+0000] {taskinstance.py:732} INFO - ::endgroup::
[2025-03-21T11:31:32.842+0000] {taskinstance.py:3313} ERROR - Task failed with exception
Traceback (most recent call last):
  File "/home/airflow/.local/lib/python3.12/site-packages/airflow/models/taskinstance.py", line 768, in _execute_task
    result = _execute_callable(context=context, **execute_callable_kwargs)
             ^^^^^^^^^^^^^^^^^^^^^^^^^^^^^^^^^^^^^^^^^^^^^^^^^^^^^^^^^^^^^
  File "/home/airflow/.local/lib/python3.12/site-packages/airflow/models/taskinstance.py", line 734, in _execute_callable
    return ExecutionCallableRunner(
           ^^^^^^^^^^^^^^^^^^^^^^^^
  File "/home/airflow/.local/lib/python3.12/site-packages/airflow/utils/operator_helpers.py", line 252, in run
    return self.func(*args, **kwargs)
           ^^^^^^^^^^^^^^^^^^^^^^^^^^
  File "/home/airflow/.local/lib/python3.12/site-packages/airflow/models/baseoperator.py", line 424, in wrapper
    return func(self, *args, **kwargs)
           ^^^^^^^^^^^^^^^^^^^^^^^^^^^
  File "/home/airflow/.local/lib/python3.12/site-packages/airflow/operators/python.py", line 238, in execute
    return_value = self.execute_callable()
                   ^^^^^^^^^^^^^^^^^^^^^^^
  File "/home/airflow/.local/lib/python3.12/site-packages/airflow/operators/python.py", line 256, in execute_callable
    return runner.run(*self.op_args, **self.op_kwargs)
           ^^^^^^^^^^^^^^^^^^^^^^^^^^^^^^^^^^^^^^^^^^^
  File "/home/airflow/.local/lib/python3.12/site-packages/airflow/utils/operator_helpers.py", line 252, in run
    return self.func(*args, **kwargs)
           ^^^^^^^^^^^^^^^^^^^^^^^^^^
  File "/opt/airflow/dags/data_ingestion_gcs_dag.py", line 29, in format_to_parquet
    table = pv.read_csv(src_file)
            ^^^^^^^^^^^^^^^^^^^^^
  File "pyarrow/_csv.pyx", line 1261, in pyarrow._csv.read_csv
  File "pyarrow/_csv.pyx", line 1270, in pyarrow._csv.read_csv
  File "pyarrow/error.pxi", line 155, in pyarrow.lib.pyarrow_internal_check_status
  File "pyarrow/error.pxi", line 92, in pyarrow.lib.check_status
OSError: zlib inflate failed: incorrect header check
[2025-03-21T11:31:32.858+0000] {taskinstance.py:1226} INFO - Marking task as FAILED. dag_id=data_ingestion_gcs_dag, task_id=format_to_parquet_task, run_id=manual__2025-03-21T11:26:23.009689+00:00, execution_date=20250321T112623, start_date=20250321T113132, end_date=20250321T113132
[2025-03-21T11:31:32.898+0000] {taskinstance.py:341} INFO - ::group::Post task execution logs
[2025-03-21T11:31:32.899+0000] {standard_task_runner.py:124} ERROR - Failed to execute job 21 for task format_to_parquet_task (zlib inflate failed: incorrect header check; 1329)
Traceback (most recent call last):
  File "/home/airflow/.local/lib/python3.12/site-packages/airflow/task/task_runner/standard_task_runner.py", line 117, in _start_by_fork
    ret = args.func(args, dag=self.dag)
          ^^^^^^^^^^^^^^^^^^^^^^^^^^^^^
  File "/home/airflow/.local/lib/python3.12/site-packages/airflow/cli/cli_config.py", line 49, in command
    return func(*args, **kwargs)
           ^^^^^^^^^^^^^^^^^^^^^
  File "/home/airflow/.local/lib/python3.12/site-packages/airflow/utils/cli.py", line 116, in wrapper
    return f(*args, **kwargs)
           ^^^^^^^^^^^^^^^^^^
  File "/home/airflow/.local/lib/python3.12/site-packages/airflow/cli/commands/task_command.py", line 483, in task_run
    task_return_code = _run_task_by_selected_method(args, _dag, ti)
                       ^^^^^^^^^^^^^^^^^^^^^^^^^^^^^^^^^^^^^^^^^^^^
  File "/home/airflow/.local/lib/python3.12/site-packages/airflow/cli/commands/task_command.py", line 256, in _run_task_by_selected_method
    return _run_raw_task(args, ti)
           ^^^^^^^^^^^^^^^^^^^^^^^
  File "/home/airflow/.local/lib/python3.12/site-packages/airflow/cli/commands/task_command.py", line 341, in _run_raw_task
    return ti._run_raw_task(
           ^^^^^^^^^^^^^^^^^
  File "/home/airflow/.local/lib/python3.12/site-packages/airflow/utils/session.py", line 97, in wrapper
    return func(*args, session=session, **kwargs)
           ^^^^^^^^^^^^^^^^^^^^^^^^^^^^^^^^^^^^^^
  File "/home/airflow/.local/lib/python3.12/site-packages/airflow/models/taskinstance.py", line 3006, in _run_raw_task
    return _run_raw_task(
           ^^^^^^^^^^^^^^
  File "/home/airflow/.local/lib/python3.12/site-packages/airflow/models/taskinstance.py", line 274, in _run_raw_task
    TaskInstance._execute_task_with_callbacks(
  File "/home/airflow/.local/lib/python3.12/site-packages/airflow/models/taskinstance.py", line 3161, in _execute_task_with_callbacks
    result = self._execute_task(context, task_orig)
             ^^^^^^^^^^^^^^^^^^^^^^^^^^^^^^^^^^^^^^
  File "/home/airflow/.local/lib/python3.12/site-packages/airflow/models/taskinstance.py", line 3185, in _execute_task
    return _execute_task(self, context, task_orig)
           ^^^^^^^^^^^^^^^^^^^^^^^^^^^^^^^^^^^^^^^
  File "/home/airflow/.local/lib/python3.12/site-packages/airflow/models/taskinstance.py", line 768, in _execute_task
    result = _execute_callable(context=context, **execute_callable_kwargs)
             ^^^^^^^^^^^^^^^^^^^^^^^^^^^^^^^^^^^^^^^^^^^^^^^^^^^^^^^^^^^^^
  File "/home/airflow/.local/lib/python3.12/site-packages/airflow/models/taskinstance.py", line 734, in _execute_callable
    return ExecutionCallableRunner(
           ^^^^^^^^^^^^^^^^^^^^^^^^
  File "/home/airflow/.local/lib/python3.12/site-packages/airflow/utils/operator_helpers.py", line 252, in run
    return self.func(*args, **kwargs)
           ^^^^^^^^^^^^^^^^^^^^^^^^^^
  File "/home/airflow/.local/lib/python3.12/site-packages/airflow/models/baseoperator.py", line 424, in wrapper
    return func(self, *args, **kwargs)
           ^^^^^^^^^^^^^^^^^^^^^^^^^^^
  File "/home/airflow/.local/lib/python3.12/site-packages/airflow/operators/python.py", line 238, in execute
    return_value = self.execute_callable()
                   ^^^^^^^^^^^^^^^^^^^^^^^
  File "/home/airflow/.local/lib/python3.12/site-packages/airflow/operators/python.py", line 256, in execute_callable
    return runner.run(*self.op_args, **self.op_kwargs)
           ^^^^^^^^^^^^^^^^^^^^^^^^^^^^^^^^^^^^^^^^^^^
  File "/home/airflow/.local/lib/python3.12/site-packages/airflow/utils/operator_helpers.py", line 252, in run
    return self.func(*args, **kwargs)
           ^^^^^^^^^^^^^^^^^^^^^^^^^^
  File "/opt/airflow/dags/data_ingestion_gcs_dag.py", line 29, in format_to_parquet
    table = pv.read_csv(src_file)
            ^^^^^^^^^^^^^^^^^^^^^
  File "pyarrow/_csv.pyx", line 1261, in pyarrow._csv.read_csv
  File "pyarrow/_csv.pyx", line 1270, in pyarrow._csv.read_csv
  File "pyarrow/error.pxi", line 155, in pyarrow.lib.pyarrow_internal_check_status
  File "pyarrow/error.pxi", line 92, in pyarrow.lib.check_status
OSError: zlib inflate failed: incorrect header check
[2025-03-21T11:31:32.949+0000] {local_task_job_runner.py:266} INFO - Task exited with return code 1
[2025-03-21T11:31:32.987+0000] {taskinstance.py:3901} INFO - 0 downstream tasks scheduled from follow-on schedule check
[2025-03-21T11:31:32.993+0000] {local_task_job_runner.py:245} INFO - ::endgroup::
